OrderBook/OrderBookTests/MockUp/bitMexMock.json
#  wss://ws.bitmex.com/realtime?subscribe=instrument,orderBookL2_25:XBTUSD

{"op": "subscribe", "args": ["orderBookL2_25:XBTUSD"]}
  {"success":true,"subscribe":"orderBookL2_25:XBTUSD","request":{"op":"subscribe","args":["orderBookL2_25:XBTUSD"]}}
  {
      "table":"orderBookL2_25",
      "keys":["symbol","id","side"],
      "types":{"id":"long","price":"float","side":"symbol","size":"long","symbol":"symbol","timestamp":"timestamp"}
      "action":"partial",
      "data":[
        {"symbol":"XBTUSD","id":17999992000,"side":"Sell","size":100,"price":80,"timestamp":"2022-02-09T11:23:06.802Z"},
        {"symbol":"XBTUSD","id":17999993000,"side":"Sell","size":20,"price":70,"timestamp":"2022-02-09T11:23:06.802Z"},
        {"symbol":"XBTUSD","id":17999994000,"side":"Sell","size":10,"price":60,"timestamp":"2022-02-09T11:23:06.802Z"},
        {"symbol":"XBTUSD","id":17999995000,"side":"Buy","size":10,"price":50,"timestamp":"2022-02-09T11:23:06.802Z"},
        {"symbol":"XBTUSD","id":17999996000,"side":"Buy","size":20,"price":40,"timestamp":"2022-02-09T11:23:06.802Z"},
        {"symbol":"XBTUSD","id":17999997000,"side":"Buy","size":100,"price":30,"timestamp":"2022-02-09T11:23:06.802Z"}
      ]
    }
  {
      "table":"orderBookL2_25",
      "action":"update",
      "data":[
        {"symbol":"XBTUSD","id":17999995000,"side":"Buy","size":5}
      ]
    }
  {
      "table":"orderBookL2_25",
      "action":"delete",
      "data":[
        {"symbol":"XBTUSD","id":17999995000,"side":"Buy"}
      ]
    }
  {
      "table":"orderBookL2_25",
      "action":"insert",
      "data":[
        {"symbol":"XBTUSD","id":17999995500,"side":"Buy","size":10,"price":45},
      ]
    }
